Traceback (most recent call last):
  File "C:\Users\omnic\local\GitRepos\chat-berta\venv\lib\site-packages\transformers\utils\import_utils.py", line 1093, in _get_module
    return importlib.import_module("." + module_name, self.__name__)
  File "C:\Python310\lib\importlib\__init__.py", line 126, in import_module
    return _bootstrap._gcd_import(name[level:], package, level)
  File "<frozen importlib._bootstrap>", line 1050, in _gcd_import
  File "<frozen importlib._bootstrap>", line 1027, in _find_and_load
  File "<frozen importlib._bootstrap>", line 1006, in _find_and_load_unlocked
  File "<frozen importlib._bootstrap>", line 688, in _load_unlocked
  File "<frozen importlib._bootstrap_external>", line 883, in exec_module
  File "<frozen importlib._bootstrap>", line 241, in _call_with_frames_removed
  File "C:\Users\omnic\local\GitRepos\chat-berta\venv\lib\site-packages\transformers\trainer.py", line 67, in <module>
    from .data.data_collator import DataCollator, DataCollatorWithPadding, default_data_collator
  File "C:\Users\omnic\local\GitRepos\chat-berta\venv\lib\site-packages\transformers\data\__init__.py", line 19, in <module>
    from .data_collator import (
  File "C:\Users\omnic\local\GitRepos\chat-berta\venv\lib\site-packages\transformers\data\data_collator.py", line 24, in <module>
    from ..models.bert import BertTokenizer, BertTokenizerFast
ImportError: cannot import name 'BertTokenizerFast' from 'transformers.models.bert' (C:\Users\omnic\local\GitRepos\chat-berta\venv\lib\site-packages\transformers\models\bert\__init__.py)

The above exception was the direct cause of the following exception:

Traceback (most recent call last):
  File "C:\Users\omnic\local\GitRepos\chat-berta\pkg-dependencies\model_test.py", line 37, in test_model_usage
    from apiutils.nec.NetworkComponent import NetworkComponent
  File "C:\Users\omnic\local\GitRepos\chat-berta\apiutils\nec\NetworkComponent.py", line 1, in <module>
    from apiutils.model.ChatBerta import ChatBerta
  File "C:\Users\omnic\local\GitRepos\chat-berta\apiutils\model\ChatBerta.py", line 4, in <module>
    from apiutils.model.chat_bert_trainer import CustomTrainer
  File "C:\Users\omnic\local\GitRepos\chat-berta\apiutils\model\chat_bert_trainer.py", line 2, in <module>
    from transformers import Trainer
  File "<frozen importlib._bootstrap>", line 1075, in _handle_fromlist
  File "C:\Users\omnic\local\GitRepos\chat-berta\venv\lib\site-packages\transformers\utils\import_utils.py", line 1083, in __getattr__
    module = self._get_module(self._class_to_module[name])
  File "C:\Users\omnic\local\GitRepos\chat-berta\venv\lib\site-packages\transformers\utils\import_utils.py", line 1095, in _get_module
    raise RuntimeError(
RuntimeError: Failed to import transformers.trainer because of the following error (look up to see its traceback):
cannot import name 'BertTokenizerFast' from 'transformers.models.bert' (C:\Users\omnic\local\GitRepos\chat-berta\venv\lib\site-packages\transformers\models\bert\__init__.py)
